Workbook
Name ExpFactor: 정확도!#REF!
Name GunType.Eng: Enum!$J$3:$J$12
Name GunType.Kor: Enum!$K$3:$K$12
Name RefAngle: 정확도!$B$2
Name SniperRefAngle: 정확도!$B$3
Name StageCategoryType.Kor: Enum!$C$4:$C$9:Enum!#REF!
Name WeaponSlotType.Kor: Enum!$C$3:$C$8
Name WeaponTacticalType.Kor: Enum!$O$3:$O$8
Name WeaponType.Kor: Enum!$G$3:$G$11

Sheet Database
A1: WeaponDB
D2: WeaponSlotType | E2: WeaponType | F2: WeaponTacticalType | G2: GunType
A3: ID | B3: 팩번호 | C3: 이름 | D3: 슬롯 | E3: 유형 | F3: 전술 유형 | G3: 총기특성 | H3: 정렬 키 | I3: 탄창 당 탄약 수 | J3: 기본 탄창 | K3: 최대 탄창 | L3: 기본 탄약 수 | M3: 최대 탄약 수 | N3: 산탄총 총알 수 | O3: 데미지 | P3: 연사속도 (RPM) | Q3: 발사간격 (초) | R3: 재장전 (초) | S3: 사거리 | T3: 피해 반경 | U3: 효과 지속 시간 (초) | V3: 리소스 설정 에셋 | W3: 구 리소스 이름 (참고용) | X3: 로드아웃 공개 여부 | Y3: 투척무기 1회구매 수량 | Z3: 투척무기광고시청 제공수량 | AA3: 구매 가격 (Gold) | AB3: 1일 대여 | AC3: 7일 대여 | AD3: 30일 대여 | AE3: 탄퍼짐 기준값 (서있을 떄) | AF3: 줌 모드에서 탄퍼짐 기준값 (서있을 때) | AG3: 앉은 상태 탄퍼짐 배수 | AH3: 걸을 때 탄퍼짐 배수 | AI3: 뛸 때 탄퍼짐 배수 | AJ3: 명중률1 | AK3: 명중률2 샷건 적용 | AL3: 초당 명중률
A4: No | B4: - | C4: Name | D4: SlotType | E4: WeaponType | F4: TacticalType | G4: GunType | H4: SortKey | I4: AmmoPerClip | J4: Clips | K4: MaxClips | L4: - | M4: - | N4: - | O4: Damage | P4: FireRate | Q4: - | R4: ReloadTime | S4: Range | T4: DamageRadius | U4: DamageDuration | V4: ResSettings | W4: - | X4: IsOpen | Y4: GrBuyCnt | Z4: GrAdRewardCnt | AA4: BuyCost | AB4: Rent1dCost | AC4: Rent7dCost | AD4: Rent30dCost | AE4: SpreadAngle | AF4: SpreadAngleZoom | AG4: SpreadSitMultiply | AH4: SpreadWalkMultiply | AI4: SpreadRunMultiply | AJ4: - | AK4: - | AL4: -
A5: 1 | B5: 기본 | C5: SMG-5R | D5: ■□□□□기본슬롯 | E5: SMG | F5: - | G5: Machinegun | H5: 1 | I5: 30 | J5: 7 | K5: 10 | L5: =I5*J5 -> 210 | M5: =I5*K5 -> 300 | N5: 1 | O5: 19 | P5: 830 | Q5: =60/P5 -> 0.072289157 | R5: 2.2 | S5: 100 | V5: SMG-1 SMG-5R (Settings) | W5: Basic/Rifle | X5: 1 | AE5: 3.8 | AF5: 1 | AG5: 0.8 | AH5: 1.7 | AI5: 3.3 | AJ5: =ROUND(IF(G5="Sniper", SniperRefAngle/Database!AF5, RefAngle/Database!AE5) * IF(OR(E5="근접 무기", E5="투척 무기"), 0, 1) *100, 2) -> 78.95 | AK5: =ROUND((1 - POWER(1-AJ5/100,N5)) * 100,2) -> 78.95 | AL5: =ROUND((1 - POWER(1-AK5/100,P5/60)) * 100,2) -> 100
A6: 2 | B6: 기본 | C6: GLK-17X | D6: □■□□□보조슬롯 | E6: 권총 | F6: - | G6: Machinegun | H6: 2 | I6: 17 | J6: 5 | K6: 10 | L6: =I6*J6 -> 85 | M6: =I6*K6 -> 170 | N6: 1 | O6: 20 | P6: 300 | Q6: =60/P6 -> 0.2 | R6: 1.6 | S6: 50 | V6: Pistol-2 GLK-17X (Settings) | W6: Basic/Pistol | X6: 1 | AB6: 30 | AC6: 210 | AD6: 840 | AE6: 4.33 | AF6: 1 | AG6: 0.8 | AH6: 1.4 | AI6: 1.8 | AJ6: =ROUND(IF(G6="Sniper", SniperRefAngle/Database!AF6, RefAngle/Database!AE6) * IF(OR(E6="근접 무기", E6="투척 무기"), 0, 1) *100, 2) -> 69.28 | AK6: =ROUND((1 - POWER(1-AJ6/100,N6)) * 100,2) -> 69.28 | AL6: =ROUND((1 - POWER(1-AK6/100,P6/60)) * 100,2) -> 99.73
A7: 3 | B7: 기본 | C7: RMC-870 | D7: ■□□□□기본슬롯 | E7: 중화기 | F7: - | G7: Shotgun | H7: 1 | I7: 6 | J7: 8 | K7: 10 | L7: =I7*J7 -> 48 | M7: =I7*K7 -> 60 | N7: 8 | O7: 17 | P7: 48 | Q7: =60/P7 -> 1.25 | R7: 4.5 | S7: 20 | V7: Shotgun-3 RMC-870 (Settings) | W7: Basic/Shotgun | X7: 1 | AE7: 13.5 | AF7: 1 | AG7: 0.9 | AH7: 1.7 | AI7: 1.8 | AJ7: =ROUND(IF(G7="Sniper", SniperRefAngle/Database!AF7, RefAngle/Database!AE7) * IF(OR(E7="근접 무기", E7="투척 무기"), 0, 1) *100, 2) -> 22.22 | AK7: =ROUND((1 - POWER(1-AJ7/100,N7)) * 100,2) -> 86.6 | AL7: =ROUND((1 - POWER(1-AK7/100,P7/60)) * 100,2) -> 79.97
A8: 4 | B8: 기본 | C8: MK2 | D8: □□□■□투척슬롯 | E8: 투척 무기 | F8: 수류탄류 | G8: Grenade | H8: 1 | I8: 1 | J8: 2 | K8: 3 | L8: =I8*J8 -> 2 | M8: =I8*K8 -> 3 | N8: 1 | O8: 81 | P8: 999 | Q8: =60/P8 -> 0.06006006 | R8: 5 | S8: 35 | T8: 14 | V8: Grenade-4 MK2 (Settings) | W8: Basic/Grenade | X8: 1 | Y8: 10 | Z8: 4 | AA8: 50 | AE8: 20 | AF8: 10 | AG8: 0.7 | AH8: 1.2 | AI8: 1.5 | AJ8: =ROUND(IF(G8="Sniper", SniperRefAngle/Database!AF8, RefAngle/Database!AE8) * IF(OR(E8="근접 무기", E8="투척 무기"), 0, 1) *100, 2) -> 0 | AK8: =ROUND((1 - POWER(1-AJ8/100,N8)) * 100,2) -> 0 | AL8: =ROUND((1 - POWER(1-AK8/100,P8/60)) * 100,2) -> 0
A9: 5 | B9: 기본 | C9: M24 | D9: ■□□□□기본슬롯 | E9: 저격소총 | F9: - | G9: Sniper | H9: 1 | I9: 10 | J9: 5 | K9: 10 | L9: =I9*J9 -> 50 | M9: =I9*K9 -> 100 | N9: 1 | O9: 83 | P9: 48 | Q9: =60/P9 -> 1.25 | R9: 2.6 | S9: 600 | V9: Sniper-5 M24 (Settings) | W9: Basic/Sniper | X9: 1 | AE9: 5.6 | AF9: 0.102 | AG9: 0.8 | AH9: 1.5 | AI9: 3 | AJ9: =ROUND(IF(G9="Sniper", SniperRefAngle/Database!AF9, RefAngle/Database!AE9) * IF(OR(E9="근접 무기", E9="투척 무기"), 0, 1) *100, 2) -> 95.98 | AK9: =ROUND((1 - POWER(1-AJ9/100,N9)) * 100,2) -> 95.98 | AL9: =ROUND((1 - POWER(1-AK9/100,P9/60)) * 100,2) -> 92.35
A10: 6 | B10: 기본 | C10: K98 | D10: □□■□□근접슬롯 | E10: 근접 무기 | F10: - | G10: Knife | H10: 1 | M10: =I10*K10 -> 0 | N10: 1 | O10: 41 | P10: 100 | Q10: =60/P10 -> 0.6 | R10: 0.9 | S10: 2 | V10: Melee-6 K98 (Settings) | W10: Basic/Knife | X10: 1 | AE10: 4 | AF10: 1 | AG10: 1 | AH10: 1 | AI10: 1 | AJ10: =ROUND(IF(G10="Sniper", SniperRefAngle/Database!AF10, RefAngle/Database!AE10) * IF(OR(E10="근접 무기", E10="투척 무기"), 0, 1) *100, 2) -> 0 | AK10: =ROUND((1 - POWER(1-AJ10/100,N10)) * 100,2) -> 0 | AL10: =ROUND((1 - POWER(1-AK10/100,P10/60)) * 100,2) -> 0
A11: 7 | B11: 기본 | C11: Molotov | D11: □□□■□투척슬롯 | E11: 투척 무기 | F11: 화염병류 | G11: Grenade | H11: 2 | I11: 1 | J11: 2 | K11: 3 | L11: =I11*J11 -> 2 | M11: =I11*K11 -> 3 | N11: 1 | O11: 15 | P11: 999 | Q11: =60/P11 -> 0.06006006 | R11: 12 | S11: 30 | T11: 8 | U11: 6 | V11: Grenade-7 Molotov (Settings) | W11: Basic/Molotov | X11: 1 | Y11: 10 | Z11: 4 | AA11: 50 | AE11: 10.21 | AF11: 0.75 | AG11: 0.7 | AH11: 1.2 | AI11: 1.5 | AJ11: =ROUND(IF(G11="Sniper", SniperRefAngle/Database!AF11, RefAngle/Database!AE11) * IF(OR(E11="근접 무기", E11="투척 무기"), 0, 1) *100, 2) -> 0 | AK11: =ROUND((1 - POWER(1-AJ11/100,N11)) * 100,2) -> 0 | AL11: =ROUND((1 - POWER(1-AK11/100,P11/60)) * 100,2) -> 0
A12: 8 | B12: 기본 | C12: M320 | D12: ■□□□□기본슬롯 | E12: 중화기 | F12: - | G12: Launcher | H12: 5 | I12: 1 | J12: 6 | K12: 6 | L12: =I12*J12 -> 6 | M12: =I12*K12 -> 6 | N12: 1 | O12: 210 | P12: 45 | Q12: =60/P12 -> 1.3333333 | R12: 2.5 | S12: 100 | V12: Launcher-8 M320 (Settings) | W12: Basic/Launcher | AE12: 4.21 | AF12: 1 | AG12: 0.9 | AH12: 2.5 | AI12: 2.5 | AJ12: =ROUND(IF(G12="Sniper", SniperRefAngle/Database!AF12, RefAngle/Database!AE12) * IF(OR(E12="근접 무기", E12="투척 무기"), 0, 1) *100, 2) -> 71.26 | AK12: =ROUND((1 - POWER(1-AJ12/100,N12)) * 100,2) -> 71.26 | AL12: =ROUND((1 - POWER(1-AK12/100,P12/60)) * 100,2) -> 60.75
A13: 9 | B13: #1 | C13: SCA-R5 | D13: ■□□□□기본슬롯 | E13: 소총 | F13: - | G13: Machinegun | H13: 5 | I13: 30 | J13: 5 | K13: 10 | L13: =I13*J13 -> 150 | M13: =I13*K13 -> 300 | N13: 1 | O13: 24 | P13: 700 | Q13: =60/P13 -> 0.085714286 | R13: 2.2 | S13: 400 | V13: Rifle-9 SCA-R5 (Settings) | W13: WP1/Rifle02 | X13: 1 | AB13: 90 | AC13: 630 | AD13: 2520 | AE13: 3.4 | AF13: 1 | AG13: 0.8 | AH13: 1.6 | AI13: 3.5 | AJ13: =ROUND(IF(G13="Sniper", SniperRefAngle/Database!AF13, RefAngle/Database!AE13) * IF(OR(E13="근접 무기", E13="투척 무기"), 0, 1) *100, 2) -> 88.24 | AK13: =ROUND((1 - POWER(1-AJ13/100,N13)) * 100,2) -> 88.24 | AL13: =ROUND((1 - POWER(1-AK13/100,P13/60)) * 100,2) -> 100
A14: 10 | B14: #1 | C14: S2-V1A | D14: ■□□□□기본슬롯 | E14: 소총 | F14: - | G14: Machinegun | H14: 2 | I14: 30 | J14: 5 | K14: 10 | L14: =I14*J14 -> 150 | M14: =I14*K14 -> 300 | N14: 1 | O14: 23 | P14: 710 | Q14: =60/P14 -> 0.084507042 | R14: 2.2 | S14: 330 | V14: Rifle-10 S2-V1A (Settings) | W14: WP1/Rifle03 | X14: 1 | AB14: 30 | AC14: 210 | AD14: 840 | AE14: 3.6 | AF14: 1 | AG14: 0.8 | AH14: 1.3 | AI14: 3 | AJ14: =ROUND(IF(G14="Sniper", SniperRefAngle/Database!AF14, RefAngle/Database!AE14) * IF(OR(E14="근접 무기", E14="투척 무기"), 0, 1) *100, 2) -> 83.33 | AK14: =ROUND((1 - POWER(1-AJ14/100,N14)) * 100,2) -> 83.33 | AL14: =ROUND((1 - POWER(1-AK14/100,P14/60)) * 100,2) -> 100
A15: 11 | B15: #1 | C15: SMG-5KX | D15: ■□□□□기본슬롯 | E15: SMG | F15: - | G15: Machinegun | H15: 3 | I15: 30 | J15: 7 | K15: 10 | L15: =I15*J15 -> 210 | M15: =I15*K15 -> 300 | N15: 1 | O15: 21 | P15: 900 | Q15: =60/P15 -> 0.066666667 | R15: 2.1 | S15: 100 | V15: SMG-11 SMG-5KX (Settings) | W15: WP1/Rifle04 | X15: 1 | AB15: 50 | AC15: 350 | AD15: 1400 | AE15: 3.75 | AF15: 1 | AG15: 0.8 | AH15: 1.5 | AI15: 3 | AJ15: =ROUND(IF(G15="Sniper", SniperRefAngle/Database!AF15, RefAngle/Database!AE15) * IF(OR(E15="근접 무기", E15="투척 무기"), 0, 1) *100, 2) -> 80 | AK15: =ROUND((1 - POWER(1-AJ15/100,N15)) * 100,2) -> 80 | AL15: =ROUND((1 - POWER(1-AK15/100,P15/60)) * 100,2) -> 100
A16: 12 | B16: #1 | C16: TACTICAL AXE | D16: □□■□□근접슬롯 | E16: 근접 무기 | F16: - | G16: Knife | H16: 5 | L16: =I16*J16 -> 0 | M16: =I16*K16 -> 0 | N16: 1 | O16: 54 | P16: 90 | Q16: =60/P16 -> 0.66666667 | R16: 1.5 | S16: 2 | V16: Melee-12 TACTICAL AXE (Settings) | W16: WP1/Axe | X16: 1 | AB16: 90 | AC16: 630 | AD16: 2520 | AE16: 4 | AF16: 1 | AG16: 1 | AH16: 1 | AI16: 1 | AJ16: =ROUND(IF(G16="Sniper", SniperRefAngle/Database!AF16, RefAngle/Database!AE16) * IF(OR(E16="근접 무기", E16="투척 무기"), 0, 1) *100, 2) -> 0 | AK16: =ROUND((1 - POWER(1-AJ16/100,N16)) * 100,2) -> 0 | AL16: =ROUND((1 - POWER(1-AK16/100,P16/60)) * 100,2) -> 0
A17: 13 | B17: #1 | C17: M26 | D17: □□□■□투척슬롯 | E17: 투척 무기 | F17: 수류탄류 | G17: Grenade | H17: 3 | I17: 1 | J17: 2 | K17: 3 | L17: =I17*J17 -> 2 | M17: =I17*K17 -> 3 | N17: 1 | O17: 83 | P17: 999 | Q17: =60/P17 -> 0.06006006 | R17: 5 | S17: 30 | T17: 12 | V17: Grenade-13 M26 (Settings) | W17: WP1/Grenade2 | X17: 1 | Y17: 10 | Z17: 4 | AA17: 50 | AE17: 20.21 | AF17: 10 | AG17: 0.7 | AH17: 1.2 | AI17: 1.5 | AJ17: =ROUND(IF(G17="Sniper", SniperRefAngle/Database!AF17, RefAngle/Database!AE17) * IF(OR(E17="근접 무기", E17="투척 무기"), 0, 1) *100, 2) -> 0 | AK17: =ROUND((1 - POWER(1-AJ17/100,N17)) * 100,2) -> 0 | AL17: =ROUND((1 - POWER(1-AK17/100,P17/60)) * 100,2) -> 0
A18: 14 | B18: #1 | C18: MK.3 | D18: □■□□□보조슬롯 | E18: 권총 | F18: - | G18: Machinegun | H18: 4 | I18: 10 | J18: 8 | K18: 10 | L18: =I18*J18 -> 80 | M18: =I18*K18 -> 100 | N18: 1 | O18: 26 | P18: 280 | Q18: =60/P18 -> 0.21428571 | R18: 1.8 | S18: 35 | V18: Pistol-14 MK3 (Settings) | W18: WP1/Pistol1 | X18: 1 | AB18: 50 | AC18: 350 | AD18: 1400 | AE18: 4.3 | AF18: 1 | AG18: 0.8 | AH18: 1.5 | AI18: 1.9 | AJ18: =ROUND(IF(G18="Sniper", SniperRefAngle/Database!AF18, RefAngle/Database!AE18) * IF(OR(E18="근접 무기", E18="투척 무기"), 0, 1) *100, 2) -> 69.77 | AK18: =ROUND((1 - POWER(1-AJ18/100,N18)) * 100,2) -> 69.77 | AL18: =ROUND((1 - POWER(1-AK18/100,P18/60)) * 100,2) -> 99.62
A19: 15 | B19: #1 | C19: PP-R9 | D19: □■□□□보조슬롯 | E19: 권총 | F19: - | G19: Machinegun | H19: 1 | I19: 10 | J19: 8 | K19: 10 | L19: =I19*J19 -> 80 | M19: =I19*K19 -> 100 | N19: 1 | O19: 18 | P19: 200 | Q19: =60/P19 -> 0.3 | R19: 1.4 | S19: 50 | V19: Pistol-15 PP-R9 (Settings) | W19: WP1/Pistol2 | X19: 1 | AE19: 4.6 | AF19: 1 | AG19: 0.8 | AH19: 1.4 | AI19: 1.8 | AJ19: =ROUND(IF(G19="Sniper", SniperRefAngle/Database!AF19, RefAngle/Database!AE19) * IF(OR(E19="근접 무기", E19="투척 무기"), 0, 1) *100, 2) -> 65.22 | AK19: =ROUND((1 - POWER(1-AJ19/100,N19)) * 100,2) -> 65.22 | AL19: =ROUND((1 - POWER(1-AK19/100,P19/60)) * 100,2) -> 97.04
A20: 16 | B20: #1 | C20: TR-444X | D20: □■□□□보조슬롯 | E20: 권총 | F20: - | G20: Machinegun | H20: 5 | I20: 6 | J20: 9 | K20: 10 | L20: =I20*J20 -> 54 | M20: =I20*K20 -> 60 | N20: 1 | O20: 31 | P20: 150 | Q20: =60/P20 -> 0.4 | R20: 3 | S20: 50 | V20: Pistol-16 TR-444X (Settings) | W20: WP1/Pistol3 | X20: 1 | AB20: 70 | AC20: 490 | AD20: 1960 | AE20: 4.28 | AF20: 1 | AG20: 0.8 | AH20: 1.6 | AI20: 1.9 | AJ20: =ROUND(IF(G20="Sniper", SniperRefAngle/Database!AF20, RefAngle/Database!AE20) * IF(OR(E20="근접 무기", E20="투척 무기"), 0, 1) *100, 2) -> 70.09 | AK20: =ROUND((1 - POWER(1-AJ20/100,N20)) * 100,2) -> 70.09 | AL20: =ROUND((1 - POWER(1-AK20/100,P20/60)) * 100,2) -> 95.11
A21: 17 | B21: #1 | C21: KUKRI | D21: □□■□□근접슬롯 | E21: 근접 무기 | F21: - | G21: Knife | H21: 2 | L21: =I21*J21 -> 0 | M21: =I21*K21 -> 0 | N21: 1 | O21: 44 | P21: 200 | Q21: =60/P21 -> 0.3 | R21: 0.7 | S21: 2 | V21: Melee-17 KUKRI (Settings) | W21: WP1/Knife2 | X21: 1 | AB21: 30 | AC21: 210 | AD21: 840 | AE21: 4 | AF21: 1 | AG21: 1 | AH21: 1 | AI21: 1 | AJ21: =ROUND(IF(G21="Sniper", SniperRefAngle/Database!AF21, RefAngle/Database!AE21) * IF(OR(E21="근접 무기", E21="투척 무기"), 0, 1) *100, 2) -> 0 | AK21: =ROUND((1 - POWER(1-AJ21/100,N21)) * 100,2) -> 0 | AL21: =ROUND((1 - POWER(1-AK21/100,P21/60)) * 100,2) -> 0
A22: 18 | B22: #1 | C22: TSG-14 | D22: ■□□□□기본슬롯 | E22: 중화기 | F22: - | G22: Shotgun | H22: 3 | I22: 6 | J22: 8 | K22: 20 | L22: =I22*J22 -> 48 | M22: =I22*K22 -> 120 | N22: 8 | O22: 18 | P22: 54 | Q22: =60/P22 -> 1.1111111 | R22: 4.2 | S22: 25 | V22: Shotgun-18 TSG-14 (Settings) | W22: WP1/ShotGun2 | X22: 1 | AB22: 70 | AC22: 490 | AD22: 1960 | AE22: 12.5 | AF22: 1 | AG22: 0.9 | AH22: 1.4 | AI22: 1.7 | AJ22: =ROUND(IF(G22="Sniper", SniperRefAngle/Database!AF22, RefAngle/Database!AE22) * IF(OR(E22="근접 무기", E22="투척 무기"), 0, 1) *100, 2) -> 24 | AK22: =ROUND((1 - POWER(1-AJ22/100,N22)) * 100,2) -> 88.87 | AL22: =ROUND((1 - POWER(1-AK22/100,P22/60)) * 100,2) -> 86.14
A23: 19 | B23: #1 | C23: AX-50S | D23: ■□□□□기본슬롯 | E23: 저격소총 | F23: - | G23: Sniper | H23: 4 | I23: 8 | J23: 5 | K23: 10 | L23: =I23*J23 -> 40 | M23: =I23*K23 -> 80 | N23: 1 | O23: 86 | P23: 48 | Q23: =60/P23 -> 1.25 | R23: 2.4 | S23: 600 | V23: Sniper-19 AX-50S (Settings) | W23: WP1/SniperRifle | X23: 1 | AB23: 70 | AC23: 490 | AD23: 1960 | AE23: 5.6 | AF23: 0.1005 | AG23: 0.8 | AH23: 1.5 | AI23: 3 | AJ23: =ROUND(IF(G23="Sniper", SniperRefAngle/Database!AF23, RefAngle/Database!AE23) * IF(OR(E23="근접 무기", E23="투척 무기"), 0, 1) *100, 2) -> 97.41 | AK23: =ROUND((1 - POWER(1-AJ23/100,N23)) * 100,2) -> 97.41 | AL23: =ROUND((1 - POWER(1-AK23/100,P23/60)) * 100,2) -> 94.62
A24: 20 | B24: #1 | C24: U-Pro | D24: ■□□□□기본슬롯 | E24: SMG | F24: - | G24: Machinegun | H24: 2 | I24: 30 | J24: 7 | K24: 10 | L24: =I24*J24 -> 210 | M24: =I24*K24 -> 300 | N24: 1 | O24: 21 | P24: 950 | Q24: =60/P24 -> 0.063157895 | R24: 2.1 | S24: 100 | V24: SMG-20 U-Pro (Settings) | W24: WP1/TommyGun | X24: 1 | AB24: 30 | AC24: 210 | AD24: 840 | AE24: 3.7 | AF24: 1 | AG24: 0.8 | AH24: 1.5 | AI24: 3 | AJ24: =ROUND(IF(G24="Sniper", SniperRefAngle/Database!AF24, RefAngle/Database!AE24) * IF(OR(E24="근접 무기", E24="투척 무기"), 0, 1) *100, 2) -> 81.08 | AK24: =ROUND((1 - POWER(1-AJ24/100,N24)) * 100,2) -> 81.08 | AL24: =ROUND((1 - POWER(1-AK24/100,P24/60)) * 100,2) -> 100
A25: 21 | B25: #1 | C25: Axe | D25: □□■□□근접슬롯 | E25: 근접 무기 | F25: - | G25: Knife | H25: 3 | L25: =I25*J25 -> 0 | M25: =I25*K25 -> 0 | N25: 1 | O25: 48 | P25: 80 | Q25: =60/P25 -> 0.75 | R25: 2 | S25: 2 | V25: Melee-21 Axe (Settings) | W25: WP1/Axe2 | X25: 1 | AB25: 50 | AC25: 350 | AD25: 1400 | AE25: 4 | AF25: 1 | AG25: 1 | AH25: 1 | AI25: 1 | AJ25: =ROUND(IF(G25="Sniper", SniperRefAngle/Database!AF25, RefAngle/Database!AE25) * IF(OR(E25="근접 무기", E25="투척 무기"), 0, 1) *100, 2) -> 0 | AK25: =ROUND((1 - POWER(1-AJ25/100,N25)) * 100,2) -> 0 | AL25: =ROUND((1 - POWER(1-AK25/100,P25/60)) * 100,2) -> 0
A26: 22 | B26: #1 | C26: M32 | D26: ■□□□□기본슬롯 | E26: 중화기 | F26: - | G26: Launcher | H26: 7 | I26: 6 | J26: 1 | K26: 2 | L26: =I26*J26 -> 6 | M26: =I26*K26 -> 12 | N26: 1 | O26: 180 | P26: 40 | Q26: =60/P26 -> 1.5 | R26: 5 | S26: 110 | V26: Launcher-22 M32 (Settings) | W26: WP1/Grenade Gun | AE26: 4.21 | AF26: 1 | AG26: 0.9 | AH26: 2.5 | AI26: 2.5 | AJ26: =ROUND(IF(G26="Sniper", SniperRefAngle/Database!AF26, RefAngle/Database!AE26) * IF(OR(E26="근접 무기", E26="투척 무기"), 0, 1) *100, 2) -> 71.26 | AK26: =ROUND((1 - POWER(1-AJ26/100,N26)) * 100,2) -> 71.26 | AL26: =ROUND((1 - POWER(1-AK26/100,P26/60)) * 100,2) -> 56.45
A27: 23 | B27: #1 | C27: DR-28H | D27: ■□□□□기본슬롯 | E27: 소총 | F27: - | G27: Machinegun | H27: 4 | I27: 30 | J27: 5 | K27: 10 | L27: =I27*J27 -> 150 | M27: =I27*K27 -> 300 | N27: 1 | O27: 24 | P27: 660 | Q27: =60/P27 -> 0.090909091 | R27: 2.4 | S27: 350 | V27: Rifle-23 DR-28H (Settings) | W27: WP1/Rifle05 | X27: 1 | AB27: 70 | AC27: 490 | AD27: 1960 | AE27: 3.5 | AF27: 1 | AG27: 0.8 | AH27: 1.7 | AI27: 3.3 | AJ27: =ROUND(IF(G27="Sniper", SniperRefAngle/Database!AF27, RefAngle/Database!AE27) * IF(OR(E27="근접 무기", E27="투척 무기"), 0, 1) *100, 2) -> 85.71 | AK27: =ROUND((1 - POWER(1-AJ27/100,N27)) * 100,2) -> 85.71 | AL27: =ROUND((1 - POWER(1-AK27/100,P27/60)) * 100,2) -> 100
A28: 24 | B28: #1 | C28: AW-X7 | D28: ■□□□□기본슬롯 | E28: 저격소총 | F28: - | G28: Sniper | H28: 3 | I28: 8 | J28: 5 | K28: 10 | L28: =I28*J28 -> 40 | M28: =I28*K28 -> 80 | N28: 1 | O28: 85 | P28: 55 | Q28: =60/P28 -> 1.0909091 | R28: 2.4 | S28: 600 | V28: Sniper-24 AW-X7 (Settings) | W28: WP1/SniperRifle2 | X28: 1 | AB28: 50 | AC28: 350 | AD28: 1400 | AE28: 5.5 | AF28: 0.101 | AG28: 0.8 | AH28: 1.4 | AI28: 2.7 | AJ28: =ROUND(IF(G28="Sniper", SniperRefAngle/Database!AF28, RefAngle/Database!AE28) * IF(OR(E28="근접 무기", E28="투척 무기"), 0, 1) *100, 2) -> 96.93 | AK28: =ROUND((1 - POWER(1-AJ28/100,N28)) * 100,2) -> 96.93 | AL28: =ROUND((1 - POWER(1-AK28/100,P28/60)) * 100,2) -> 95.9
A29: 25 | B29: #2 | C29: M4A1 | D29: ■□□□□기본슬롯 | E29: 소총 | F29: - | G29: Machinegun | H29: 3 | I29: 30 | J29: 5 | K29: 10 | L29: =I29*J29 -> 150 | M29: =I29*K29 -> 300 | N29: 1 | O29: 23 | P29: 700 | Q29: =60/P29 -> 0.085714286 | R29: 2.3 | S29: 330 | V29: Rifle-25 M4A1 (Settings) | W29: WP2/Rifle6 | X29: 1 | AB29: 50 | AC29: 350 | AD29: 1400 | AE29: 3.6 | AF29: 1 | AG29: 0.8 | AH29: 1.4 | AI29: 3.2 | AJ29: =ROUND(IF(G29="Sniper", SniperRefAngle/Database!AF29, RefAngle/Database!AE29) * IF(OR(E29="근접 무기", E29="투척 무기"), 0, 1) *100, 2) -> 83.33 | AK29: =ROUND((1 - POWER(1-AJ29/100,N29)) * 100,2) -> 83.33 | AL29: =ROUND((1 - POWER(1-AK29/100,P29/60)) * 100,2) -> 100
A30: 26 | B30: #2 | C30: KX-9 | D30: ■□□□□기본슬롯 | E30: SMG | F30: - | G30: Machinegun | H30: 4 | I30: 30 | J30: 7 | K30: 10 | L30: =I30*J30 -> 210 | M30: =I30*K30 -> 300 | N30: 1 | O30: 22 | P30: 830 | Q30: =60/P30 -> 0.072289157 | R30: 2.1 | S30: 100 | V30: SMG-26 KX-9 (Settings) | W30: WP2/SMG4 | X30: 1 | AB30: 70 | AC30: 490 | AD30: 1960 | AE30: 3.6 | AF30: 1 | AG30: 0.8 | AH30: 1.6 | AI30: 3.2 | AJ30: =ROUND(IF(G30="Sniper", SniperRefAngle/Database!AF30, RefAngle/Database!AE30) * IF(OR(E30="근접 무기", E30="투척 무기"), 0, 1) *100, 2) -> 83.33 | AK30: =ROUND((1 - POWER(1-AJ30/100,N30)) * 100,2) -> 83.33 | AL30: =ROUND((1 - POWER(1-AK30/100,P30/60)) * 100,2) -> 100
A31: 27 | B31: #2 | C31: GLK-18X | D31: □■□□□보조슬롯 | E31: 권총 | F31: - | G31: Machinegun | H31: 6 | I31: 19 | J31: 5 | K31: 10 | L31: =I31*J31 -> 95 | M31: =I31*K31 -> 190 | N31: 1 | O31: 20 | P31: 320 | Q31: =60/P31 -> 0.1875 | R31: 1.6 | S31: 50 | V31: Pistol-27 GLK-18X (Settings) | W31: WP2/Pistol4 | X31: 1 | AB31: 90 | AC31: 630 | AD31: 2520 | AE31: 4.3 | AF31: 1 | AG31: 0.8 | AH31: 1.4 | AI31: 1.8 | AJ31: =ROUND(IF(G31="Sniper", SniperRefAngle/Database!AF31, RefAngle/Database!AE31) * IF(OR(E31="근접 무기", E31="투척 무기"), 0, 1) *100, 2) -> 69.77 | AK31: =ROUND((1 - POWER(1-AJ31/100,N31)) * 100,2) -> 69.77 | AL31: =ROUND((1 - POWER(1-AK31/100,P31/60)) * 100,2) -> 99.83
A32: 28 | B32: #2 | C32: SPZ-12 | D32: ■□□□□기본슬롯 | E32: 중화기 | F32: - | G32: Shotgun | H32: 4 | I32: 8 | J32: 6 | K32: 10 | L32: =I32*J32 -> 48 | M32: =I32*K32 -> 80 | N32: 8 | O32: 18 | P32: 48 | Q32: =60/P32 -> 1.25 | R32: 4.7 | S32: 20 | V32: Shotgun-28 SPZ-12 (Settings) | W32: WP2/ShotGun4 | X32: 1 | AB32: 90 | AC32: 630 | AD32: 2520 | AE32: 13.2 | AF32: 1 | AG32: 0.9 | AH32: 1.7 | AI32: 1.9 | AJ32: =ROUND(IF(G32="Sniper", SniperRefAngle/Database!AF32, RefAngle/Database!AE32) * IF(OR(E32="근접 무기", E32="투척 무기"), 0, 1) *100, 2) -> 22.73 | AK32: =ROUND((1 - POWER(1-AJ32/100,N32)) * 100,2) -> 87.29 | AL32: =ROUND((1 - POWER(1-AK32/100,P32/60)) * 100,2) -> 80.8
A33: 29 | B33: #2 | C33: M24-Custom | D33: ■□□□□기본슬롯 | E33: 저격소총 | F33: - | G33: Sniper | H33: 2 | I33: 10 | J33: 5 | K33: 10 | L33: =I33*J33 -> 50 | M33: =I33*K33 -> 100 | N33: 1 | O33: 85 | P33: 55 | Q33: =60/P33 -> 1.0909091 | R33: 2.4 | S33: 600 | V33: Sniper-29 M24-Custom (Settings) | W33: WP2/SniperRifle3 | X33: 1 | AB33: 30 | AC33: 210 | AD33: 840 | AE33: 5.4 | AF33: 0.1 | AG33: 0.8 | AH33: 1.4 | AI33: 2.5 | AJ33: =ROUND(IF(G33="Sniper", SniperRefAngle/Database!AF33, RefAngle/Database!AE33) * IF(OR(E33="근접 무기", E33="투척 무기"), 0, 1) *100, 2) -> 97.9 | AK33: =ROUND((1 - POWER(1-AJ33/100,N33)) * 100,2) -> 97.9 | AL33: =ROUND((1 - POWER(1-AK33/100,P33/60)) * 100,2) -> 97.1
A34: 30 | B34: #2 | C34: UMR-9 | D34: ■□□□□기본슬롯 | E34: SMG | F34: - | G34: Machinegun | H34: 5 | I34: 30 | J34: 7 | K34: 10 | L34: =I34*J34 -> 210 | M34: =I34*K34 -> 300 | N34: 1 | O34: 22 | P34: 850 | Q34: =60/P34 -> 0.070588235 | R34: 2 | S34: 100 | V34: SMG-30 UMR-9 (Settings) | W34: WP2/SMG5 | X34: 1 | AB34: 90 | AC34: 630 | AD34: 2520 | AE34: 3.7 | AF34: 1 | AG34: 0.8 | AH34: 1.8 | AI34: 3.3 | AJ34: =ROUND(IF(G34="Sniper", SniperRefAngle/Database!AF34, RefAngle/Database!AE34) * IF(OR(E34="근접 무기", E34="투척 무기"), 0, 1) *100, 2) -> 81.08 | AK34: =ROUND((1 - POWER(1-AJ34/100,N34)) * 100,2) -> 81.08 | AL34: =ROUND((1 - POWER(1-AK34/100,P34/60)) * 100,2) -> 100
A35: 31 | B35: #2 | C35: Mk1A | D35: ■□□□□기본슬롯 | E35: 중화기 | F35: - | G35: Launcher | H35: 6 | I35: 6 | J35: 1 | K35: 2 | L35: =I35*J35 -> 6 | M35: =I35*K35 -> 12 | N35: 1 | O35: 195 | P35: 40 | Q35: =60/P35 -> 1.5 | R35: 4.5 | S35: 130 | V35: Launcher-22 Mk1A (Settings) | W35: WP2/Grenade Gun3 | AE35: 4.21 | AF35: 1 | AG35: 0.9 | AH35: 2.5 | AI35: 2.5 | AJ35: =ROUND(IF(G35="Sniper", SniperRefAngle/Database!AF35, RefAngle/Database!AE35) * IF(OR(E35="근접 무기", E35="투척 무기"), 0, 1) *100, 2) -> 71.26 | AK35: =ROUND((1 - POWER(1-AJ35/100,N35)) * 100,2) -> 71.26 | AL35: =ROUND((1 - POWER(1-AK35/100,P35/60)) * 100,2) -> 56.45
A36: 32 | B36: #2 | C36: MG429 | D36: ■□□□□기본슬롯 | E36: 중화기 | F36: - | G36: Shotgun | H36: 2 | I36: 2 | J36: 20 | K36: 40 | L36: =I36*J36 -> 40 | M36: =I36*K36 -> 80 | N36: 8 | O36: 26 | P36: 75 | Q36: =60/P36 -> 0.8 | R36: 2.2 | S36: 20 | V36: Shotgun-32 MG429 (Settings) | W36: WP2/Double Barrel | X36: 1 | AB36: 30 | AC36: 210 | AD36: 840 | AE36: 12 | AF36: 1 | AG36: 0.9 | AH36: 1.3 | AI36: 1.6 | AJ36: =ROUND(IF(G36="Sniper", SniperRefAngle/Database!AF36, RefAngle/Database!AE36) * IF(OR(E36="근접 무기", E36="투척 무기"), 0, 1) *100, 2) -> 25 | AK36: =ROUND((1 - POWER(1-AJ36/100,N36)) * 100,2) -> 89.99 | AL36: =ROUND((1 - POWER(1-AK36/100,P36/60)) * 100,2) -> 94.37
A37: 33 | B37: #2 | C37: RHO-44 | D37: □■□□□보조슬롯 | E37: 권총 | F37: - | G37: Machinegun | H37: 3 | I37: 6 | J37: 9 | K37: 10 | L37: =I37*J37 -> 54 | M37: =I37*K37 -> 60 | N37: 1 | O37: 33 | P37: 150 | Q37: =60/P37 -> 0.4 | R37: 3 | S37: 50 | V37: Pistol-33 RHO-44 (Settings) | W37: WP2/Pistol5 | X37: 1 | AB37: 30 | AC37: 210 | AD37: 840 | AE37: 4.5 | AF37: 1 | AG37: 0.8 | AH37: 1.6 | AI37: 2 | AJ37: =ROUND(IF(G37="Sniper", SniperRefAngle/Database!AF37, RefAngle/Database!AE37) * IF(OR(E37="근접 무기", E37="투척 무기"), 0, 1) *100, 2) -> 66.67 | AK37: =ROUND((1 - POWER(1-AJ37/100,N37)) * 100,2) -> 66.67 | AL37: =ROUND((1 - POWER(1-AK37/100,P37/60)) * 100,2) -> 93.59
A38: 34 | B38: #2 | C38: HT-X50 | D38: ■□□□□기본슬롯 | E38: 저격소총 | F38: - | G38: Sniper | H38: 5 | I38: 7 | J38: 5 | K38: 10 | L38: =I38*J38 -> 35 | M38: =I38*K38 -> 70 | N38: 1 | O38: 87 | P38: 45 | Q38: =60/P38 -> 1.3333333 | R38: 2.6 | S38: 600 | V38: Sniper-34 HT-X50 (Settings) | W38: WP2/SniperRifle4 | X38: 1 | AB38: 90 | AC38: 630 | AD38: 2520 | AE38: 5.5 | AF38: 0.102 | AG38: 0.8 | AH38: 1.5 | AI38: 3 | AJ38: =ROUND(IF(G38="Sniper", SniperRefAngle/Database!AF38, RefAngle/Database!AE38) * IF(OR(E38="근접 무기", E38="투척 무기"), 0, 1) *100, 2) -> 95.98 | AK38: =ROUND((1 - POWER(1-AJ38/100,N38)) * 100,2) -> 95.98 | AL38: =ROUND((1 - POWER(1-AK38/100,P38/60)) * 100,2) -> 91.02
A39: 35 | B39: #2 | C39: AK-74 | D39: ■□□□□기본슬롯 | E39: 소총 | F39: - | G39: Machinegun | H39: 1 | I39: 30 | J39: 5 | K39: 10 | L39: =I39*J39 -> 150 | M39: =I39*K39 -> 300 | N39: 1 | O39: 21 | P39: 670 | Q39: =60/P39 -> 0.089552239 | R39: 2.4 | S39: 350 | V39: Rifle-35 2AK-74 (Settings) | W39: WP2/Rifle7 | X39: 1 | AE39: 3.7 | AF39: 1 | AG39: 0.8 | AH39: 1.8 | AI39: 3.5 | AJ39: =ROUND(IF(G39="Sniper", SniperRefAngle/Database!AF39, RefAngle/Database!AE39) * IF(OR(E39="근접 무기", E39="투척 무기"), 0, 1) *100, 2) -> 81.08 | AK39: =ROUND((1 - POWER(1-AJ39/100,N39)) * 100,2) -> 81.08 | AL39: =ROUND((1 - POWER(1-AK39/100,P39/60)) * 100,2) -> 100
A40: 36 | B40: #2 | C40: PKM | D40: ■□□□□기본슬롯 | E40: 소총 | F40: - | G40: Machinegun | H40: 6 | I40: 80 | J40: 3 | K40: 6 | L40: =I40*J40 -> 240 | M40: =I40*K40 -> 480 | N40: 1 | O40: 20 | P40: 730 | Q40: =60/P40 -> 0.082191781 | R40: 4.8 | S40: 400 | V40: Rifle-36 PKM (Settings) | W40: WP2/LMG | X40: 1 | AB40: 100 | AC40: 700 | AD40: 2800 | AE40: 5 | AF40: 1 | AG40: 0.9 | AH40: 2.5 | AI40: 5.5 | AJ40: =ROUND(IF(G40="Sniper", SniperRefAngle/Database!AF40, RefAngle/Database!AE40) * IF(OR(E40="근접 무기", E40="투척 무기"), 0, 1) *100, 2) -> 60 | AK40: =ROUND((1 - POWER(1-AJ40/100,N40)) * 100,2) -> 60 | AL40: =ROUND((1 - POWER(1-AK40/100,P40/60)) * 100,2) -> 100
...

Sheet Enum
A1: WeaponSlotType | E1: WeaponType | I1: GunType | M1: WeaponTacticalType
A2: id | B2: name | C2: nameKor | E2: id | F2: name | G2: nameKor | I2: id | J2: name | K2: nameKor | M2: id | N2: name | O2: nameKor
A3: 0 | B3: None | C3: - | E3: 0 | F3: None | G3: - | I3: 99 | J3: None | K3: - | M3: 0 | N3: None | O3: -
A4: 1 | B4: MainGun | C4: ■□□□□기본슬롯 | E4: 1 | F4: Pistol | G4: 권총 | I4: 0 | J4: Shotgun | K4: 샷건 | M4: 1 | N4: Smoke | O4: 연막탄
A5: 2 | B5: SideGun | C5: □■□□□보조슬롯 | E5: 2 | F5: HeavyWeapon | G5: 중화기 | I5: 1 | J5: Machinegun | K5: 머신건(연사) | M5: 2 | N5: Flash | O5: 섬광탄
A6: 3 | B6: Melee | C6: □□■□□근접슬롯 | E6: 3 | F6: SMG | G6: SMG | I6: 2 | J6: Sniper | K6: 스나이퍼 | M6: 3 | N6: UAV | O6: UAV
A7: 4 | B7: Grenade | C7: □□□■□투척슬롯 | E7: 4 | F7: Rifle | G7: 소총 | I7: 3 | J7: Pistol | K7: 권총(단발) | M7: 4 | N7: Grenade | O7: 수류탄류
A8: 5 | B8: Tactical | C8: □□□□■전술슬롯 | E8: 5 | F8: Sniper | G8: 저격소총 | I8: 4 | J8: Burst | K8: 버스트(점사) | M8: 5 | N8: Molotov | O8: 화염병류
E9: 6 | F9: Grenade | G9: 투척 무기 | I9: 5 | J9: Grenade | K9: 투척형
E10: 7 | F10: Melee | G10: 근접 무기 | I10: 6 | J10: Knife | K10: 근접형
E11: 8 | F11: Tactical | G11: 전술 무기 | I11: 7 | J11: Launcher | K11: 런쳐
I12: 8 | J12: HandItem | K12: 핸드 아이템
E13: 무기 형태에 따른 구분
I14: 동작 특성에 따른 구분

Sheet Export
A1: [Client]
A2: DB_SOURCE | B2: Database,A1
A3: DB_OUTPUT | B3: $CLIENT/Weapon.json
A4: DB_OUTPUT_BIN | B4: $CLIENT/Weapon.cdb.bytes
A5: DB_ENUM_ROW | B5: 2
A6: DB_FIELD_ROW | B6: 4
A7: DB_RECORD_ROW | B7: 5
A8: DB_ID_COL | B8: 1
A9: No | B9: I
A10: Name | B10: T
A11: SlotType | B11: I
A12: WeaponType | B12: I
A13: TacticalType | B13: I
A14: GunType | B14: I
A15: AmmoPerClip | B15: I
A16: Clips | B16: I
A17: MaxClips | B17: I
A18: ReloadTime | B18: R
A19: FireRate | B19: R
A20: Damage | B20: I
... A37: SortKey | B37: I

Sheet Desr
A1: Weapon_Table 컬럼 설명
A2: 이름 | B2: 설명
A3: Id | B3: Weapon_Table의 유니크 키입니다. 중복 사용이 불가능합니다. 해당 테이블은 총의 정보를 기재하는 테이블입니다. Weapon_Table은 1000~1999 영역을 사용합니다.
A4: WeaponName | B4: 무기 이름을 기재하는 컬럼입니다.
A5: WeaponType | B5: 무기 타입을 분류하는 컬럼입니다. 무기 타입은 5가지 타입으로 분류됩니다. (0 : Main, 1: Sub, 2 : Melee, 3 : Grenades, 4 : Gear) Main 타입으로 분류된 무기는 하나만 소지할 수 있으며, Main 타입으로 분류된 무기를 구매하는 경우 해당 무기를 드롭하고 교체합니다. Sub 타입 또한, 서브로 분류된 무기 하나만 소지할 수 있으며, Sub 무기 타입으로 분류된 무기를 구매하는 경우 해당 무기를 드롭하고 교체합니다. Melee, Grenades, Gear로 분류된 장비는 각각 하나씩 소지할 수 있으며 여러 개를 구매할 수 있습니다.
A6: WeaponPrice | B6: 무기 가격을 기재하는 컬럼입니다. 0을 입력하는 경우 무료로 사용할 수 있습니다.
A7: BasicAmmo | B7: 총의 기본 탄약 수를 기재하는 컬럼입니다.
A8: SpareAmmo | B8: 총의 전체 탄약 수를 기재하는 컬럼입니다. (Ex. AK-47은 기본 탄약 30발에 예비 탄약 120발)
A9: ReloadTime | B9: 재장전 시간을 기재하는 컬럼입니다. (1초 = 1000으로 설정합니다.)
A10: EquipChangeTime | B10: 장비 교체 시간을 기재하는 컬럼입니다. (1초 = 1000으로 설정합니다.)
A11: Rate | B11: 연사력 (RPM)을 기재하는 컬럼입니다. RPM은 분당 발사 하는 시간을 나타내며, 한 발을 발사하고 다음 발을 발사할 때 까지 걸리는 시간을 의미합니다. RPM의 공식은 60/발사 간격(초)입니다. 1초 = 1000으로 설정합니다. (Ex. AK-47의 연사력 100 → 0.1/60 = 600 RPM 이므로, 분당 600발 사격)
A12: DistanceDmgIndex | B12: DistanceDmg_Table의 Index를 참조하여 사용되는 컬럼입니다. 무기 별 거리마다 데미지 수치를 다르게 설정합니다.
A13: Distance | B13: 총의 사거리를 기재하는 컬럼입니다. {1 = 1000로 설정합니다. (Ex. AK-47의 사거리는 7000 → 70m)}
... A16: ScopeButtonPrint | B16: 조준 버튼 활성화를 기재하는 컬럼입니다. 조준 버튼은 스나이퍼 무기만 출력되며, True인 경우 조준 버튼을 활성화합니다. 조준 고정 배율은 Const_Table의 수치를 참조합니다.
A17: WeaponImage
A18: WeaponModel
A19: SpreadMaxAngle | B19: 탄퍼짐 (최대)각도
A20: SpreadStandMultiply | B20: 서있는 경우 탄퍼짐에 대한 보정 배수 ( SpreadMaxAngle * SpreadStandMultiply)
A21: SpreadWalkMultiply | B21: 걸어가는 경우 (속도 기준) 탄퍼짐에 대한 보정 배수 ( SpreadMaxAngle * SpreadWalkMultiply)
A22: SpreadRunMultiply | B22: 뛰어가는 경우 (속도 기준) 탄퍼짐에 대한 보정 배수 ( SpreadMaxAngle * SpreadRunMultiply)
A23: SpreadZoomMultiply | B23: Sniper 아닌경우, Zoom에서 탄퍼짐 배수
A24: SpreadAngleNoZoomSniper | B24: Sniper 이면서, Zoom 없을 때 탄퍼짐 배수

Sheet 정확도
B1: 정확도 100%인 경우 탄퍼짐 기준 각도
B2: 3 | C2: RefAngle | D2: 일반 총기 기준 각도
B3: 0.0979 | C3: SniperRefAngle | D3: 저격종 기준 각도 (Zoom 상태의 각도가 적용됨)
B6: ■탄퍼짐 각도에 따라 탄착군 면적은 근사적으로 제곱에 비례한다.
B7: ■정확도는 우리방식(원주좌표계에서 랜덤 R, 랜덤 θ로 탄착 결정)에서는 탄퍼짐 각도(≒탄착군 반지름)에 반비례
B8: ■정확도 = (RefAngle / SpreadAngle) 여기서 저격총은 RefAngle 대신 SniperRefAngle을 사용
B9: ■Database시트의 '확인용' 필드값을 위해 위 RefAngle, SniperRefAngle, ExpFactor을 적절히 조절해 볼것 (결정된 값은 Misc DB의 GunAccuracyFactors값에 반영할 것)
B10: ■ExpFactor는 이론상 제곱이나, 탄착군이 중앙에 몰리는 경향이 있다면 2보다 약간 작을 수 있다.
B11: ■산탄총의 경우: n개의 총알에 대해 전체 명중 확률 = 1 - (1 - p)n 즉, 탄 1발 명중 확률 = 20%이면 8발에 대해 1 - (1 - 0.2)8 = 83%

Sheet DV-IDENTITY-0
A1: =IF(Database!2:2,"AAAAAFP/3wA=",0) -> 0 | B1: =AND(Database!A2,"AAAAAFP/3wE=") -> #VALUE! | C1: =AND(Database!#REF!,"AAAAAFP/3wI=") -> #REF! | D1: =AND(Database!#REF!,"AAAAAFP/3wM=") -> #REF! | E1: =AND(Database!#REF!,"AAAAAFP/3wQ=") -> #REF! | F1: =AND(Database!#REF!,"AAAAAFP/3wU=") -> #REF! | G1: =AND(Database!#REF!,"AAAAAFP/3wY=") -> #REF! | H1: =AND(Database!#REF!,"AAAAAFP/3wc=") -> #REF! | I1: =AND(Database!#REF!,"AAAAAFP/3wg=") -> #REF! | J1: =AND(Database!#REF!,"AAAAAFP/3wk=") -> #REF! | K1: =AND(Database!#REF!,"AAAAAFP/3wo=") -> #REF! | L1: =AND(Database!#REF!,"AAAAAFP/3ws=") -> #REF! | M1: =AND(Database!#REF!,"AAAAAFP/3ww=") -> #REF! | N1: =IF(Database!4:4,"AAAAAFP/3w0=",0) -> #VALUE! | O1: =AND(Database!A4,"AAAAAFP/3w4=") -> #VALUE! | P1: =AND(Database!#REF!,"AAAAAFP/3w8=") -> #REF! | Q1: =AND(Database!#REF!,"AAAAAFP/3xA=") -> #REF! | R1: =AND(Database!#REF!,"AAAAAFP/3xE=") -> #REF! | S1: =AND(Database!#REF!,"AAAAAFP/3xI=") -> #REF! | T1: =AND(Database!#REF!,"AAAAAFP/3xM=") -> #REF! | U1: =AND(Database!#REF!,"AAAAAFP/3xQ=") -> #REF! | V1: =AND(Database!#REF!,"AAAAAFP/3xU=") -> #REF! | W1: =AND(Database!#REF!,"AAAAAFP/3xY=") -> #REF! | X1: =AND(Database!#REF!,"AAAAAFP/3xc=") -> #REF! | Y1: =AND(Database!#REF!,"AAAAAFP/3xg=") -> #REF! | Z1: =AND(Database!#REF!,"AAAAAFP/3xk=") -> #REF! | AA1: =IF(Database!#REF!,"AAAAAFP/3xo=",0) -> #REF! | AB1: =AND(Database!#REF!,"AAAAAFP/3xs=") -> #REF! | AC1: =AND(Database!#REF!,"AAAAAFP/3xw=") -> #REF! | AD1: =AND(Database!#REF!,"AAAAAFP/3x0=") -> #REF! | AE1: =AND(Database!#REF!,"AAAAAFP/3x4=") -> #REF! | AF1: =AND(Database!#REF!,"AAAAAFP/3x8=") -> #REF! | AG1: =AND(Database!#REF!,"AAAAAFP/3yA=") -> #REF! | AH1: =AND(Database!#REF!,"AAAAAFP/3yE=") -> #REF! | AI1: =AND(Database!#REF!,"AAAAAFP/3yI=") -> #REF! | AJ1: =AND(Database!#REF!,"AAAAAFP/3yM=") -> #REF! | AK1: =AND(Database!#REF!,"AAAAAFP/3yQ=") -> #REF! | AL1: =AND(Database!#REF!,"AAAAAFP/3yU=") -> #REF! | AM1: =AND(Database!#REF!,"AAAAAFP/3yY=") -> #REF! | AN1: =IF(Database!#REF!,"AAAAAFP/3yc=",0) -> #REF! | AO1: =AND(Database!#REF!,"AAAAAFP/3yg=") -> #REF! | AP1: =AND(Database!#REF!,"AAAAAFP/3yk=") -> #REF! | AQ1: =AND(Database!#REF!,"AAAAAFP/3yo=") -> #REF! | AR1: =AND(Database!#REF!,"AAAAAFP/3ys=") -> #REF! | AS1: =AND(Database!#REF!,"AAAAAFP/3yw=") -> #REF! | AT1: =AND(Database!#REF!,"AAAAAFP/3y0=") -> #REF! | AU1: =AND(Database!#REF!,"AAAAAFP/3y4=") -> #REF! | AV1: =AND(Database!#REF!,"AAAAAFP/3y8=") -> #REF! | AW1: =AND(Database!#REF!,"AAAAAFP/3zA=") -> #REF! | AX1: =AND(Database!#REF!,"AAAAAFP/3zE=") -> #REF! | AY1: =AND(Database!#REF!,"AAAAAFP/3zI=") -> #REF! | AZ1: =AND(Database!#REF!,"AAAAAFP/3zM=") -> #REF! | BA1: =IF(Database!#REF!,"AAAAAFP/3zQ=",0) -> #REF! | BB1: =AND(Database!#REF!,"AAAAAFP/3zU=") -> #REF! | BC1: =AND(Database!#REF!,"AAAAAFP/3zY=") -> #REF! | BD1: =AND(Database!#REF!,"AAAAAFP/3zc=") -> #REF! | BE1: =AND(Database!#REF!,"AAAAAFP/3zg=") -> #REF! | BF1: =AND(Database!#REF!,"AAAAAFP/3zk=") -> #REF! | BG1: =AND(Database!#REF!,"AAAAAFP/3zo=") -> #REF! | BH1: =AND(Database!#REF!,"AAAAAFP/3zs=") -> #REF! | BI1: =AND(Database!#REF!,"AAAAAFP/3zw=") -> #REF! | BJ1: =AND(Database!#REF!,"AAAAAFP/3z0=") -> #REF! | BK1: =AND(Database!#REF!,"AAAAAFP/3z4=") -> #REF! | BL1: =AND(Database!#REF!,"AAAAAFP/3z8=") -> #REF! | BM1: =AND(Database!#REF!,"AAAAAFP/30A=") -> #REF! | BN1: =IF(Database!#REF!,"AAAAAFP/30E=",0) -> #REF! | BO1: =AND(Database!#REF!,"AAAAAFP/30I=") -> #REF! | BP1: =AND(Database!#REF!,"AAAAAFP/30M=") -> #REF! | BQ1: =AND(Database!#REF!,"AAAAAFP/30Q=") -> #REF! | BR1: =AND(Database!#REF!,"AAAAAFP/30U=") -> #REF! | BS1: =AND(Database!#REF!,"AAAAAFP/30Y=") -> #REF! | BT1: =AND(Database!#REF!,"AAAAAFP/30c=") -> #REF! | BU1: =AND(Database!#REF!,"AAAAAFP/30g=") -> #REF! | BV1: =AND(Database!#REF!,"AAAAAFP/30k=") -> #REF! | BW1: =AND(Database!#REF!,"AAAAAFP/30o=") -> #REF! | BX1: =AND(Database!#REF!,"AAAAAFP/30s=") -> #REF! | BY1: =AND(Database!#REF!,"AAAAAFP/30w=") -> #REF! | BZ1: =AND(Database!#REF!,"AAAAAFP/300=") -> #REF! | CA1: =IF(Database!#REF!,"AAAAAFP/304=",0) -> #REF! | CB1: =AND(Database!#REF!,"AAAAAFP/308=") -> #REF! | CC1: =AND(Database!#REF!,"AAAAAFP/31A=") -> #REF! | CD1: =AND(Database!#REF!,"AAAAAFP/31E=") -> #REF! | CE1: =AND(Database!#REF!,"AAAAAFP/31I=") -> #REF! | CF1: =AND(Database!#REF!,"AAAAAFP/31M=") -> #REF! | CG1: =AND(Database!#REF!,"AAAAAFP/31Q=") -> #REF! | CH1: =AND(Database!#REF!,"AAAAAFP/31U=") -> #REF! | CI1: =AND(Database!#REF!,"AAAAAFP/31Y=") -> #REF! | CJ1: =AND(Database!#REF!,"AAAAAFP/31c=") -> #REF! | CK1: =AND(Database!#REF!,"AAAAAFP/31g=") -> #REF! | CL1: =AND(Database!#REF!,"AAAAAFP/31k=") -> #REF! | CM1: =AND(Database!#REF!,"AAAAAFP/31o=") -> #REF! | CN1: =IF(Database!#REF!,"AAAAAFP/31s=",0) -> #REF! | CO1: =AND(Database!#REF!,"AAAAAFP/31w=") -> #REF! | CP1: =AND(Database!#REF!,"AAAAAFP/310=") -> #REF! | CQ1: =AND(Database!#REF!,"AAAAAFP/314=") -> #REF! | CR1: =AND(Database!#REF!,"AAAAAFP/318=") -> #REF! | CS1: =AND(Database!#REF!,"AAAAAFP/32A=") -> #REF! | CT1: =AND(Database!#REF!,"AAAAAFP/32E=") -> #REF! | CU1: =AND(Database!#REF!,"AAAAAFP/32I=") -> #REF! | CV1: =AND(Database!#REF!,"AAAAAFP/32M=") -> #REF! | CW1: =AND(Database!#REF!,"AAAAAFP/32Q=") -> #REF! | CX1: =AND(Database!#REF!,"AAAAAFP/32U=") -> #REF! | CY1: =AND(Database!#REF!,"AAAAAFP/32Y=") -> #REF! | CZ1: =AND(Database!#REF!,"AAAAAFP/32c=") -> #REF! | DA1: =IF(Database!#REF!,"AAAAAFP/32g=",0) -> #REF! | DB1: =AND(Database!#REF!,"AAAAAFP/32k=") -> #REF! | DC1: =AND(Database!#REF!,"AAAAAFP/32o=") -> #REF! | DD1: =AND(Database!#REF!,"AAAAAFP/32s=") -> #REF! | DE1: =AND(Database!#REF!,"AAAAAFP/32w=") -> #REF! | DF1: =AND(Database!#REF!,"AAAAAFP/320=") -> #REF! | DG1: =AND(Database!#REF!,"AAAAAFP/324=") -> #REF! | DH1: =AND(Database!#REF!,"AAAAAFP/328=") -> #REF! | DI1: =AND(Database!#REF!,"AAAAAFP/33A=") -> #REF! | DJ1: =AND(Database!#REF!,"AAAAAFP/33E=") -> #REF! | DK1: =AND(Database!#REF!,"AAAAAFP/33I=") -> #REF! | DL1: =AND(Database!#REF!,"AAAAAFP/33M=") -> #REF! | DM1: =AND(Database!#REF!,"AAAAAFP/33Q=") -> #REF! | DN1: =IF(Database!#REF!,"AAAAAFP/33U=",0) -> #REF! | DO1: =AND(Database!#REF!,"AAAAAFP/33Y=") -> #REF! | DP1: =AND(Database!#REF!,"AAAAAFP/33c=") -> #REF! | DQ1: =AND(Database!#REF!,"AAAAAFP/33g=") -> #REF! | DR1: =AND(Database!#REF!,"AAAAAFP/33k=") -> #REF! | DS1: =AND(Database!#REF!,"AAAAAFP/33o=") -> #REF! | DT1: =AND(Database!#REF!,"AAAAAFP/33s=") -> #REF! | DU1: =AND(Database!#REF!,"AAAAAFP/33w=") -> #REF! | DV1: =AND(Database!#REF!,"AAAAAFP/330=") -> #REF! | DW1: =AND(Database!#REF!,"AAAAAFP/334=") -> #REF! | DX1: =AND(Database!#REF!,"AAAAAFP/338=") -> #REF! | DY1: =AND(Database!#REF!,"AAAAAFP/34A=") -> #REF! | DZ1: =AND(Database!#REF!,"AAAAAFP/34E=") -> #REF! | EA1: =IF(Database!#REF!,"AAAAAFP/34I=",0) -> #REF! | EB1: =AND(Database!#REF!,"AAAAAFP/34M=") -> #REF! | EC1: =AND(Database!#REF!,"AAAAAFP/34Q=") -> #REF! | ED1: =AND(Database!#REF!,"AAAAAFP/34U=") -> #REF! | EE1: =AND(Database!#REF!,"AAAAAFP/34Y=") -> #REF! | EF1: =AND(Database!#REF!,"AAAAAFP/34c=") -> #REF! | EG1: =AND(Database!#REF!,"AAAAAFP/34g=") -> #REF! | EH1: =AND(Database!#REF!,"AAAAAFP/34k=") -> #REF! | EI1: =AND(Database!#REF!,"AAAAAFP/34o=") -> #REF! | EJ1: =AND(Database!#REF!,"AAAAAFP/34s=") -> #REF! | EK1: =AND(Database!#REF!,"AAAAAFP/34w=") -> #REF! | EL1: =AND(Database!#REF!,"AAAAAFP/340=") -> #REF! | EM1: =AND(Database!#REF!,"AAAAAFP/344=") -> #REF! | EN1: =IF(Database!#REF!,"AAAAAFP/348=",0) -> #REF! | EO1: =AND(Database!#REF!,"AAAAAFP/35A=") -> #REF! | EP1: =AND(Database!#REF!,"AAAAAFP/35E=") -> #REF! | EQ1: =AND(Database!#REF!,"AAAAAFP/35I=") -> #REF! | ER1: =AND(Database!#REF!,"AAAAAFP/35M=") -> #REF! | ES1: =AND(Database!#REF!,"AAAAAFP/35Q=") -> #REF! | ET1: =AND(Database!#REF!,"AAAAAFP/35U=") -> #REF! | EU1: =AND(Database!#REF!,"AAAAAFP/35Y=") -> #REF! | EV1: =AND(Database!#REF!,"AAAAAFP/35c=") -> #REF! | EW1: =AND(Database!#REF!,"AAAAAFP/35g=") -> #REF! | EX1: =AND(Database!#REF!,"AAAAAFP/35k=") -> #REF! | EY1: =AND(Database!#REF!,"AAAAAFP/35o=") -> #REF! | EZ1: =AND(Database!#REF!,"AAAAAFP/35s=") -> #REF! | FA1: =IF(Database!#REF!,"AAAAAFP/35w=",0) -> #REF! | FB1: =AND(Database!#REF!,"AAAAAFP/350=") -> #REF! | FC1: =AND(Database!#REF!,"AAAAAFP/354=") -> #REF! | FD1: =AND(Database!#REF!,"AAAAAFP/358=") -> #REF! | FE1: =AND(Database!#REF!,"AAAAAFP/36A=") -> #REF! | FF1: =AND(Database!#REF!,"AAAAAFP/36E=") -> #REF! | FG1: =AND(Database!#REF!,"AAAAAFP/36I=") -> #REF! | FH1: =AND(Database!#REF!,"AAAAAFP/36M=") -> #REF! | FI1: =AND(Database!#REF!,"AAAAAFP/36Q=") -> #REF! | FJ1: =AND(Database!#REF!,"AAAAAFP/36U=") -> #REF! | FK1: =AND(Database!#REF!,"AAAAAFP/36Y=") -> #REF! | FL1: =AND(Database!#REF!,"AAAAAFP/36c=") -> #REF! | FM1: =AND(Database!#REF!,"AAAAAFP/36g=") -> #REF! | FN1: =IF(Database!#REF!,"AAAAAFP/36k=",0) -> #REF! | FO1: =AND(Database!#REF!,"AAAAAFP/36o=") -> #REF! | FP1: =AND(Database!#REF!,"AAAAAFP/36s=") -> #REF! | FQ1: =AND(Database!#REF!,"AAAAAFP/36w=") -> #REF! | FR1: =AND(Database!#REF!,"AAAAAFP/360=") -> #REF! | FS1: =AND(Database!#REF!,"AAAAAFP/364=") -> #REF! | FT1: =AND(Database!#REF!,"AAAAAFP/368=") -> #REF! | FU1: =AND(Database!#REF!,"AAAAAFP/37A=") -> #REF! | FV1: =AND(Database!#REF!,"AAAAAFP/37E=") -> #REF! | FW1: =AND(Database!#REF!,"AAAAAFP/37I=") -> #REF! | FX1: =AND(Database!#REF!,"AAAAAFP/37M=") -> #REF! | FY1: =AND(Database!#REF!,"AAAAAFP/37Q=") -> #REF! | FZ1: =AND(Database!#REF!,"AAAAAFP/37U=") -> #REF! | GA1: =IF(Database!#REF!,"AAAAAFP/37Y=",0) -> #REF! | GB1: =AND(Database!#REF!,"AAAAAFP/37c=") -> #REF! | GC1: =AND(Database!#REF!,"AAAAAFP/37g=") -> #REF! | GD1: =AND(Database!#REF!,"AAAAAFP/37k=") -> #REF! | GE1: =AND(Database!#REF!,"AAAAAFP/37o=") -> #REF! | GF1: =AND(Database!#REF!,"AAAAAFP/37s=") -> #REF! | GG1: =AND(Database!#REF!,"AAAAAFP/37w=") -> #REF! | GH1: =AND(Database!#REF!,"AAAAAFP/370=") -> #REF! | GI1: =AND(Database!#REF!,"AAAAAFP/374=") -> #REF! | GJ1: =AND(Database!#REF!,"AAAAAFP/378=") -> #REF! | GK1: =AND(Database!#REF!,"AAAAAFP/38A=") -> #REF! | GL1: =AND(Database!#REF!,"AAAAAFP/38E=") -> #REF! | GM1: =AND(Database!#REF!,"AAAAAFP/38I=") -> #REF! | GN1: =IF(Database!#REF!,"AAAAAFP/38M=",0) -> #REF! | GO1: =AND(Database!#REF!,"AAAAAFP/38Q=") -> #REF! | GP1: =AND(Database!#REF!,"AAAAAFP/38U=") -> #REF! | GQ1: =AND(Database!#REF!,"AAAAAFP/38Y=") -> #REF! | GR1: =AND(Database!#REF!,"AAAAAFP/38c=") -> #REF! | GS1: =AND(Database!#REF!,"AAAAAFP/38g=") -> #REF! | GT1: =AND(Database!#REF!,"AAAAAFP/38k=") -> #REF! | GU1: =AND(Database!#REF!,"AAAAAFP/38o=") -> #REF! | GV1: =AND(Database!#REF!,"AAAAAFP/38s=") -> #REF! | GW1: =AND(Database!#REF!,"AAAAAFP/38w=") -> #REF! | GX1: =AND(Database!#REF!,"AAAAAFP/380=") -> #REF! | GY1: =AND(Database!#REF!,"AAAAAFP/384=") -> #REF! | GZ1: =AND(Database!#REF!,"AAAAAFP/388=") -> #REF! | HA1: =IF(Database!#REF!,"AAAAAFP/39A=",0) -> #REF! | HB1: =AND(Database!#REF!,"AAAAAFP/39E=") -> #REF! | HC1: =AND(Database!#REF!,"AAAAAFP/39I=") -> #REF! | HD1: =AND(Database!#REF!,"AAAAAFP/39M=") -> #REF! | HE1: =AND(Database!#REF!,"AAAAAFP/39Q=") -> #REF! | HF1: =AND(Database!#REF!,"AAAAAFP/39U=") -> #REF! | HG1: =AND(Database!#REF!,"AAAAAFP/39Y=") -> #REF! | HH1: =AND(Database!#REF!,"AAAAAFP/39c=") -> #REF! | HI1: =AND(Database!#REF!,"AAAAAFP/39g=") -> #REF! | HJ1: =AND(Database!#REF!,"AAAAAFP/39k=") -> #REF! | HK1: =AND(Database!#REF!,"AAAAAFP/39o=") -> #REF! | HL1: =AND(Database!#REF!,"AAAAAFP/39s=") -> #REF! | HM1: =AND(Database!#REF!,"AAAAAFP/39w=") -> #REF! | HN1: =IF(Database!#REF!,"AAAAAFP/390=",0) -> #REF! | HO1: =AND(Database!#REF!,"AAAAAFP/394=") -> #REF! | HP1: =AND(Database!#REF!,"AAAAAFP/398=") -> #REF! | HQ1: =AND(Database!#REF!,"AAAAAFP/3+A=") -> #REF! | HR1: =AND(Database!#REF!,"AAAAAFP/3+E=") -> #REF! | HS1: =AND(Database!#REF!,"AAAAAFP/3+I=") -> #REF! | HT1: =AND(Database!#REF!,"AAAAAFP/3+M=") -> #REF! | HU1: =AND(Database!#REF!,"AAAAAFP/3+Q=") -> #REF! | HV1: =AND(Database!#REF!,"AAAAAFP/3+U=") -> #REF! | HW1: =AND(Database!#REF!,"AAAAAFP/3+Y=") -> #REF! | HX1: =AND(Database!#REF!,"AAAAAFP/3+c=") -> #REF! | HY1: =AND(Database!#REF!,"AAAAAFP/3+g=") -> #REF! | HZ1: =AND(Database!#REF!,"AAAAAFP/3+k=") -> #REF! | IA1: =IF(Database!#REF!,"AAAAAFP/3+o=",0) -> #REF! | IB1: =AND(Database!#REF!,"AAAAAFP/3+s=") -> #REF! | IC1: =AND(Database!#REF!,"AAAAAFP/3+w=") -> #REF! | ID1: =AND(Database!#REF!,"AAAAAFP/3+0=") -> #REF! | IE1: =AND(Database!#REF!,"AAAAAFP/3+4=") -> #REF! | IF1: =AND(Database!#REF!,"AAAAAFP/3+8=") -> #REF! | IG1: =AND(Database!#REF!,"AAAAAFP/3/A=") -> #REF! | IH1: =AND(Database!#REF!,"AAAAAFP/3/E=") -> #REF! | II1: =AND(Database!#REF!,"AAAAAFP/3/I=") -> #REF! | IJ1: =AND(Database!#REF!,"AAAAAFP/3/M=") -> #REF! | IK1: =AND(Database!#REF!,"AAAAAFP/3/Q=") -> #REF! | IL1: =AND(Database!#REF!,"AAAAAFP/3/U=") -> #REF! | IM1: =AND(Database!#REF!,"AAAAAFP/3/Y=") -> #REF! | IN1: =IF(Database!#REF!,"AAAAAFP/3/c=",0) -> #REF! | IO1: =AND(Database!#REF!,"AAAAAFP/3/g=") -> #REF! | IP1: =AND(Database!#REF!,"AAAAAFP/3/k=") -> #REF! | IQ1: =AND(Database!#REF!,"AAAAAFP/3/o=") -> #REF! | IR1: =AND(Database!#REF!,"AAAAAFP/3/s=") -> #REF! | IS1: =AND(Database!#REF!,"AAAAAFP/3/w=") -> #REF! | IT1: =AND(Database!#REF!,"AAAAAFP/3/0=") -> #REF! | IU1: =AND(Database!#REF!,"AAAAAFP/3/4=") -> #REF! | IV1: =AND(Database!#REF!,"AAAAAFP/3/8=") -> #REF!
A2: =AND(Database!#REF!,"AAAAAB9h+QA=") -> #REF! | B2: =AND(Database!#REF!,"AAAAAB9h+QE=") -> #REF! | C2: =AND(Database!#REF!,"AAAAAB9h+QI=") -> #REF! | D2: =AND(Database!#REF!,"AAAAAB9h+QM=") -> #REF! | E2: =IF(Database!#REF!,"AAAAAB9h+QQ=",0) -> #REF! | F2: =AND(Database!#REF!,"AAAAAB9h+QU=") -> #REF! | G2: =AND(Database!#REF!,"AAAAAB9h+QY=") -> #REF! | H2: =AND(Database!#REF!,"AAAAAB9h+Qc=") -> #REF! | I2: =AND(Database!#REF!,"AAAAAB9h+Qg=") -> #REF! | J2: =AND(Database!#REF!,"AAAAAB9h+Qk=") -> #REF! | K2: =AND(Database!#REF!,"AAAAAB9h+Qo=") -> #REF! | L2: =AND(Database!#REF!,"AAAAAB9h+Qs=") -> #REF! | M2: =AND(Database!#REF!,"AAAAAB9h+Qw=") -> #REF! | N2: =AND(Database!#REF!,"AAAAAB9h+Q0=") -> #REF! | O2: =AND(Database!#REF!,"AAAAAB9h+Q4=") -> #REF! | P2: =AND(Database!#REF!,"AAAAAB9h+Q8=") -> #REF! | Q2: =AND(Database!#REF!,"AAAAAB9h+RA=") -> #REF! | R2: =IF(Database!#REF!,"AAAAAB9h+RE=",0) -> #REF! | S2: =AND(Database!#REF!,"AAAAAB9h+RI=") -> #REF! | T2: =AND(Database!#REF!,"AAAAAB9h+RM=") -> #REF! | U2: =AND(Database!#REF!,"AAAAAB9h+RQ=") -> #REF! | V2: =AND(Database!#REF!,"AAAAAB9h+RU=") -> #REF! | W2: =AND(Database!#REF!,"AAAAAB9h+RY=") -> #REF! | X2: =AND(Database!#REF!,"AAAAAB9h+Rc=") -> #REF! | Y2: =AND(Database!#REF!,"AAAAAB9h+Rg=") -> #REF! | Z2: =AND(Database!#REF!,"AAAAAB9h+Rk=") -> #REF! | AA2: =AND(Database!#REF!,"AAAAAB9h+Ro=") -> #REF! | AB2: =AND(Database!#REF!,"AAAAAB9h+Rs=") -> #REF! | AC2: =AND(Database!#REF!,"AAAAAB9h+Rw=") -> #REF! | AD2: =AND(Database!#REF!,"AAAAAB9h+R0=") -> #REF! | AE2: =IF(Database!#REF!,"AAAAAB9h+R4=",0) -> #REF! | AF2: =AND(Database!#REF!,"AAAAAB9h+R8=") -> #REF! | AG2: =AND(Database!#REF!,"AAAAAB9h+SA=") -> #REF! | AH2: =AND(Database!#REF!,"AAAAAB9h+SE=") -> #REF! | AI2: =AND(Database!#REF!,"AAAAAB9h+SI=") -> #REF! | AJ2: =AND(Database!#REF!,"AAAAAB9h+SM=") -> #REF! | AK2: =AND(Database!#REF!,"AAAAAB9h+SQ=") -> #REF! | AL2: =AND(Database!#REF!,"AAAAAB9h+SU=") -> #REF! | AM2: =AND(Database!#REF!,"AAAAAB9h+SY=") -> #REF! | AN2: =AND(Database!#REF!,"AAAAAB9h+Sc=") -> #REF! | AO2: =AND(Database!#REF!,"AAAAAB9h+Sg=") -> #REF! | AP2: =AND(Database!#REF!,"AAAAAB9h+Sk=") -> #REF! | AQ2: =AND(Database!#REF!,"AAAAAB9h+So=") -> #REF! | AR2: =IF(Database!#REF!,"AAAAAB9h+Ss=",0) -> #REF! | AS2: =AND(Database!#REF!,"AAAAAB9h+Sw=") -> #REF! | AT2: =AND(Database!#REF!,"AAAAAB9h+S0=") -> #REF! | AU2: =AND(Database!#REF!,"AAAAAB9h+S4=") -> #REF! | AV2: =AND(Database!#REF!,"AAAAAB9h+S8=") -> #REF! | AW2: =AND(Database!#REF!,"AAAAAB9h+TA=") -> #REF! | AX2: =AND(Database!#REF!,"AAAAAB9h+TE=") -> #REF! | AY2: =AND(Database!#REF!,"AAAAAB9h+TI=") -> #REF! | AZ2: =AND(Database!#REF!,"AAAAAB9h+TM=") -> #REF! | BA2: =AND(Database!#REF!,"AAAAAB9h+TQ=") -> #REF! | BB2: =AND(Database!#REF!,"AAAAAB9h+TU=") -> #REF! | BC2: =AND(Database!#REF!,"AAAAAB9h+TY=") -> #REF! | BD2: =AND(Database!#REF!,"AAAAAB9h+Tc=") -> #REF! | BE2: =IF(Database!#REF!,"AAAAAB9h+Tg=",0) -> #REF! | BF2: =AND(Database!#REF!,"AAAAAB9h+Tk=") -> #REF! | BG2: =AND(Database!#REF!,"AAAAAB9h+To=") -> #REF! | BH2: =AND(Database!#REF!,"AAAAAB9h+Ts=") -> #REF! | BI2: =AND(Database!#REF!,"AAAAAB9h+Tw=") -> #REF! | BJ2: =AND(Database!#REF!,"AAAAAB9h+T0=") -> #REF! | BK2: =AND(Database!#REF!,"AAAAAB9h+T4=") -> #REF! | BL2: =AND(Database!#REF!,"AAAAAB9h+T8=") -> #REF! | BM2: =AND(Database!#REF!,"AAAAAB9h+UA=") -> #REF! | BN2: =AND(Database!#REF!,"AAAAAB9h+UE=") -> #REF! | BO2: =AND(Database!#REF!,"AAAAAB9h+UI=") -> #REF! | BP2: =AND(Database!#REF!,"AAAAAB9h+UM=") -> #REF! | BQ2: =AND(Database!#REF!,"AAAAAB9h+UQ=") -> #REF! | BR2: =IF(Database!#REF!,"AAAAAB9h+UU=",0) -> #REF! | BS2: =AND(Database!#REF!,"AAAAAB9h+UY=") -> #REF! | BT2: =AND(Database!#REF!,"AAAAAB9h+Uc=") -> #REF! | BU2: =AND(Database!#REF!,"AAAAAB9h+Ug=") -> #REF! | BV2: =AND(Database!#REF!,"AAAAAB9h+Uk=") -> #REF! | BW2: =AND(Database!#REF!,"AAAAAB9h+Uo=") -> #REF! | BX2: =AND(Database!#REF!,"AAAAAB9h+Us=") -> #REF! | BY2: =AND(Database!#REF!,"AAAAAB9h+Uw=") -> #REF! | BZ2: =AND(Database!#REF!,"AAAAAB9h+U0=") -> #REF! | CA2: =AND(Database!#REF!,"AAAAAB9h+U4=") -> #REF! | CB2: =AND(Database!#REF!,"AAAAAB9h+U8=") -> #REF! | CC2: =AND(Database!#REF!,"AAAAAB9h+VA=") -> #REF! | CD2: =AND(Database!#REF!,"AAAAAB9h+VE=") -> #REF! | CE2: =IF(Database!#REF!,"AAAAAB9h+VI=",0) -> #REF! | CF2: =AND(Database!#REF!,"AAAAAB9h+VM=") -> #REF! | CG2: =AND(Database!#REF!,"AAAAAB9h+VQ=") -> #REF! | CH2: =AND(Database!#REF!,"AAAAAB9h+VU=") -> #REF! | CI2: =AND(Database!#REF!,"AAAAAB9h+VY=") -> #REF! | CJ2: =AND(Database!#REF!,"AAAAAB9h+Vc=") -> #REF! | CK2: =AND(Database!#REF!,"AAAAAB9h+Vg=") -> #REF! | CL2: =AND(Database!#REF!,"AAAAAB9h+Vk=") -> #REF! | CM2: =AND(Database!#REF!,"AAAAAB9h+Vo=") -> #REF! | CN2: =AND(Database!#REF!,"AAAAAB9h+Vs=") -> #REF! | CO2: =AND(Database!#REF!,"AAAAAB9h+Vw=") -> #REF! | CP2: =AND(Database!#REF!,"AAAAAB9h+V0=") -> #REF! | CQ2: =AND(Database!#REF!,"AAAAAB9h+V4=") -> #REF! | CR2: =IF(Database!#REF!,"AAAAAB9h+V8=",0) -> #REF! | CS2: =AND(Database!#REF!,"AAAAAB9h+WA=") -> #REF! | CT2: =AND(Database!#REF!,"AAAAAB9h+WE=") -> #REF! | CU2: =AND(Database!#REF!,"AAAAAB9h+WI=") -> #REF! | CV2: =AND(Database!#REF!,"AAAAAB9h+WM=") -> #REF! | CW2: =AND(Database!#REF!,"AAAAAB9h+WQ=") -> #REF! | CX2: =AND(Database!#REF!,"AAAAAB9h+WU=") -> #REF! | CY2: =AND(Database!#REF!,"AAAAAB9h+WY=") -> #REF! | CZ2: =AND(Database!#REF!,"AAAAAB9h+Wc=") -> #REF! | DA2: =AND(Database!#REF!,"AAAAAB9h+Wg=") -> #REF! | DB2: =AND(Database!#REF!,"AAAAAB9h+Wk=") -> #REF! | DC2: =AND(Database!#REF!,"AAAAAB9h+Wo=") -> #REF! | DD2: =AND(Database!#REF!,"AAAAAB9h+Ws=") -> #REF! | DE2: =IF(Database!#REF!,"AAAAAB9h+Ww=",0) -> #REF! | DF2: =AND(Database!#REF!,"AAAAAB9h+W0=") -> #REF! | DG2: =AND(Database!#REF!,"AAAAAB9h+W4=") -> #REF! | DH2: =AND(Database!#REF!,"AAAAAB9h+W8=") -> #REF! | DI2: =AND(Database!#REF!,"AAAAAB9h+XA=") -> #REF! | DJ2: =AND(Database!#REF!,"AAAAAB9h+XE=") -> #REF! | DK2: =AND(Database!#REF!,"AAAAAB9h+XI=") -> #REF! | DL2: =AND(Database!#REF!,"AAAAAB9h+XM=") -> #REF! | DM2: =AND(Database!#REF!,"AAAAAB9h+XQ=") -> #REF! | DN2: =AND(Database!#REF!,"AAAAAB9h+XU=") -> #REF! | DO2: =AND(Database!#REF!,"AAAAAB9h+XY=") -> #REF! | DP2: =AND(Database!#REF!,"AAAAAB9h+Xc=") -> #REF! | DQ2: =AND(Database!#REF!,"AAAAAB9h+Xg=") -> #REF! | DR2: =IF(Database!#REF!,"AAAAAB9h+Xk=",0) -> #REF! | DS2: =AND(Database!#REF!,"AAAAAB9h+Xo=") -> #REF! | DT2: =AND(Database!#REF!,"AAAAAB9h+Xs=") -> #REF! | DU2: =AND(Database!#REF!,"AAAAAB9h+Xw=") -> #REF! | DV2: =AND(Database!#REF!,"AAAAAB9h+X0=") -> #REF! | DW2: =AND(Database!#REF!,"AAAAAB9h+X4=") -> #REF! | DX2: =AND(Database!#REF!,"AAAAAB9h+X8=") -> #REF! | DY2: =AND(Database!#REF!,"AAAAAB9h+YA=") -> #REF! | DZ2: =AND(Database!#REF!,"AAAAAB9h+YE=") -> #REF! | EA2: =AND(Database!#REF!,"AAAAAB9h+YI=") -> #REF! | EB2: =AND(Database!#REF!,"AAAAAB9h+YM=") -> #REF! | EC2: =AND(Database!#REF!,"AAAAAB9h+YQ=") -> #REF! | ED2: =AND(Database!#REF!,"AAAAAB9h+YU=") -> #REF! | EE2: =IF(Database!#REF!,"AAAAAB9h+YY=",0) -> #REF! | EF2: =AND(Database!#REF!,"AAAAAB9h+Yc=") -> #REF! | EG2: =AND(Database!#REF!,"AAAAAB9h+Yg=") -> #REF! | EH2: =AND(Database!#REF!,"AAAAAB9h+Yk=") -> #REF! | EI2: =AND(Database!#REF!,"AAAAAB9h+Yo=") -> #REF! | EJ2: =AND(Database!#REF!,"AAAAAB9h+Ys=") -> #REF! | EK2: =AND(Database!#REF!,"AAAAAB9h+Yw=") -> #REF! | EL2: =AND(Database!#REF!,"AAAAAB9h+Y0=") -> #REF! | EM2: =AND(Database!#REF!,"AAAAAB9h+Y4=") -> #REF! | EN2: =AND(Database!#REF!,"AAAAAB9h+Y8=") -> #REF! | EO2: =AND(Database!#REF!,"AAAAAB9h+ZA=") -> #REF! | EP2: =AND(Database!#REF!,"AAAAAB9h+ZE=") -> #REF! | EQ2: =AND(Database!#REF!,"AAAAAB9h+ZI=") -> #REF! | ER2: =IF(Database!#REF!,"AAAAAB9h+ZM=",0) -> #REF! | ES2: =AND(Database!#REF!,"AAAAAB9h+ZQ=") -> #REF! | ET2: =AND(Database!#REF!,"AAAAAB9h+ZU=") -> #REF! | EU2: =AND(Database!#REF!,"AAAAAB9h+ZY=") -> #REF! | EV2: =AND(Database!#REF!,"AAAAAB9h+Zc=") -> #REF! | EW2: =AND(Database!#REF!,"AAAAAB9h+Zg=") -> #REF! | EX2: =AND(Database!#REF!,"AAAAAB9h+Zk=") -> #REF! | EY2: =AND(Database!#REF!,"AAAAAB9h+Zo=") -> #REF! | EZ2: =AND(Database!#REF!,"AAAAAB9h+Zs=") -> #REF! | FA2: =AND(Database!#REF!,"AAAAAB9h+Zw=") -> #REF! | FB2: =AND(Database!#REF!,"AAAAAB9h+Z0=") -> #REF! | FC2: =AND(Database!#REF!,"AAAAAB9h+Z4=") -> #REF! | FD2: =AND(Database!#REF!,"AAAAAB9h+Z8=") -> #REF! | FE2: =IF(Database!#REF!,"AAAAAB9h+aA=",0) -> #REF! | FF2: =AND(Database!#REF!,"AAAAAB9h+aE=") -> #REF! | FG2: =AND(Database!#REF!,"AAAAAB9h+aI=") -> #REF! | FH2: =AND(Database!#REF!,"AAAAAB9h+aM=") -> #REF! | FI2: =AND(Database!#REF!,"AAAAAB9h+aQ=") -> #REF! | FJ2: =AND(Database!#REF!,"AAAAAB9h+aU=") -> #REF! | FK2: =AND(Database!#REF!,"AAAAAB9h+aY=") -> #REF! | FL2: =AND(Database!#REF!,"AAAAAB9h+ac=") -> #REF! | FM2: =AND(Database!#REF!,"AAAAAB9h+ag=") -> #REF! | FN2: =AND(Database!#REF!,"AAAAAB9h+ak=") -> #REF! | FO2: =AND(Database!#REF!,"AAAAAB9h+ao=") -> #REF! | FP2: =AND(Database!#REF!,"AAAAAB9h+as=") -> #REF! | FQ2: =AND(Database!#REF!,"AAAAAB9h+aw=") -> #REF! | FR2: =IF(Database!#REF!,"AAAAAB9h+a0=",0) -> #REF! | FS2: =AND(Database!#REF!,"AAAAAB9h+a4=") -> #REF! | FT2: =AND(Database!#REF!,"AAAAAB9h+a8=") -> #REF! | FU2: =AND(Database!#REF!,"AAAAAB9h+bA=") -> #REF! | FV2: =AND(Database!#REF!,"AAAAAB9h+bE=") -> #REF! | FW2: =AND(Database!#REF!,"AAAAAB9h+bI=") -> #REF! | FX2: =AND(Database!#REF!,"AAAAAB9h+bM=") -> #REF! | FY2: =AND(Database!#REF!,"AAAAAB9h+bQ=") -> #REF! | FZ2: =AND(Database!#REF!,"AAAAAB9h+bU=") -> #REF! | GA2: =AND(Database!#REF!,"AAAAAB9h+bY=") -> #REF! | GB2: =AND(Database!#REF!,"AAAAAB9h+bc=") -> #REF! | GC2: =AND(Database!#REF!,"AAAAAB9h+bg=") -> #REF! | GD2: =AND(Database!#REF!,"AAAAAB9h+bk=") -> #REF! | GE2: =IF(Database!#REF!,"AAAAAB9h+bo=",0) -> #REF! | GF2: =AND(Database!#REF!,"AAAAAB9h+bs=") -> #REF! | GG2: =AND(Database!#REF!,"AAAAAB9h+bw=") -> #REF! | GH2: =AND(Database!#REF!,"AAAAAB9h+b0=") -> #REF! | GI2: =AND(Database!#REF!,"AAAAAB9h+b4=") -> #REF! | GJ2: =AND(Database!#REF!,"AAAAAB9h+b8=") -> #REF! | GK2: =AND(Database!#REF!,"AAAAAB9h+cA=") -> #REF! | GL2: =AND(Database!#REF!,"AAAAAB9h+cE=") -> #REF! | GM2: =AND(Database!#REF!,"AAAAAB9h+cI=") -> #REF! | GN2: =AND(Database!#REF!,"AAAAAB9h+cM=") -> #REF! | GO2: =AND(Database!#REF!,"AAAAAB9h+cQ=") -> #REF! | GP2: =AND(Database!#REF!,"AAAAAB9h+cU=") -> #REF! | GQ2: =AND(Database!#REF!,"AAAAAB9h+cY=") -> #REF! | GR2: =IF(Database!#REF!,"AAAAAB9h+cc=",0) -> #REF! | GS2: =AND(Database!#REF!,"AAAAAB9h+cg=") -> #REF! | GT2: =AND(Database!#REF!,"AAAAAB9h+ck=") -> #REF! | GU2: =AND(Database!#REF!,"AAAAAB9h+co=") -> #REF! | GV2: =AND(Database!#REF!,"AAAAAB9h+cs=") -> #REF! | GW2: =AND(Database!#REF!,"AAAAAB9h+cw=") -> #REF! | GX2: =AND(Database!#REF!,"AAAAAB9h+c0=") -> #REF! | GY2: =AND(Database!#REF!,"AAAAAB9h+c4=") -> #REF! | GZ2: =AND(Database!#REF!,"AAAAAB9h+c8=") -> #REF! | HA2: =AND(Database!#REF!,"AAAAAB9h+dA=") -> #REF! | HB2: =AND(Database!#REF!,"AAAAAB9h+dE=") -> #REF! | HC2: =AND(Database!#REF!,"AAAAAB9h+dI=") -> #REF! | HD2: =AND(Database!#REF!,"AAAAAB9h+dM=") -> #REF! | HE2: =IF(Database!#REF!,"AAAAAB9h+dQ=",0) -> #REF! | HF2: =AND(Database!#REF!,"AAAAAB9h+dU=") -> #REF! | HG2: =AND(Database!#REF!,"AAAAAB9h+dY=") -> #REF! | HH2: =AND(Database!#REF!,"AAAAAB9h+dc=") -> #REF! | HI2: =AND(Database!#REF!,"AAAAAB9h+dg=") -> #REF! | HJ2: =AND(Database!#REF!,"AAAAAB9h+dk=") -> #REF! | HK2: =AND(Database!#REF!,"AAAAAB9h+do=") -> #REF! | HL2: =AND(Database!#REF!,"AAAAAB9h+ds=") -> #REF! | HM2: =AND(Database!#REF!,"AAAAAB9h+dw=") -> #REF! | HN2: =AND(Database!#REF!,"AAAAAB9h+d0=") -> #REF! | HO2: =AND(Database!#REF!,"AAAAAB9h+d4=") -> #REF! | HP2: =AND(Database!#REF!,"AAAAAB9h+d8=") -> #REF! | HQ2: =AND(Database!#REF!,"AAAAAB9h+eA=") -> #REF! | HR2: =IF(Database!#REF!,"AAAAAB9h+eE=",0) -> #REF! | HS2: =AND(Database!#REF!,"AAAAAB9h+eI=") -> #REF! | HT2: =AND(Database!#REF!,"AAAAAB9h+eM=") -> #REF! | HU2: =AND(Database!#REF!,"AAAAAB9h+eQ=") -> #REF! | HV2: =AND(Database!#REF!,"AAAAAB9h+eU=") -> #REF! | HW2: =AND(Database!#REF!,"AAAAAB9h+eY=") -> #REF! | HX2: =AND(Database!#REF!,"AAAAAB9h+ec=") -> #REF! | HY2: =AND(Database!#REF!,"AAAAAB9h+eg=") -> #REF! | HZ2: =AND(Database!#REF!,"AAAAAB9h+ek=") -> #REF! | IA2: =AND(Database!#REF!,"AAAAAB9h+eo=") -> #REF! | IB2: =AND(Database!#REF!,"AAAAAB9h+es=") -> #REF! | IC2: =AND(Database!#REF!,"AAAAAB9h+ew=") -> #REF! | ID2: =AND(Database!#REF!,"AAAAAB9h+e0=") -> #REF! | IE2: =IF(Database!#REF!,"AAAAAB9h+e4=",0) -> #REF! | IF2: =AND(Database!#REF!,"AAAAAB9h+e8=") -> #REF! | IG2: =AND(Database!#REF!,"AAAAAB9h+fA=") -> #REF! | IH2: =AND(Database!#REF!,"AAAAAB9h+fE=") -> #REF! | II2: =AND(Database!#REF!,"AAAAAB9h+fI=") -> #REF! | IJ2: =AND(Database!#REF!,"AAAAAB9h+fM=") -> #REF! | IK2: =AND(Database!#REF!,"AAAAAB9h+fQ=") -> #REF! | IL2: =AND(Database!#REF!,"AAAAAB9h+fU=") -> #REF! | IM2: =AND(Database!#REF!,"AAAAAB9h+fY=") -> #REF! | IN2: =AND(Database!#REF!,"AAAAAB9h+fc=") -> #REF! | IO2: =AND(Database!#REF!,"AAAAAB9h+fg=") -> #REF! | IP2: =AND(Database!#REF!,"AAAAAB9h+fk=") -> #REF! | IQ2: =AND(Database!#REF!,"AAAAAB9h+fo=") -> #REF! | IR2: =IF(Database!#REF!,"AAAAAB9h+fs=",0) -> #REF! | IS2: =AND(Database!#REF!,"AAAAAB9h+fw=") -> #REF! | IT2: =AND(Database!#REF!,"AAAAAB9h+f0=") -> #REF! | IU2: =AND(Database!#REF!,"AAAAAB9h+f4=") -> #REF! | IV2: =AND(Database!#REF!,"AAAAAB9h+f8=") -> #REF!
